Making dataset for object 003_cracker_box
Dataset loaded, beginning training
Traceback (most recent call last):
  File "neurals/scripts/train_classifier.py", line 142, in <module>
    main()
  File "neurals/scripts/train_classifier.py", line 90, in main
    latent_state = model.encode(pcd, tip_pos)
  File "/home/sirius/sirui/contact_planning_dexterous_hand/neurals/dex_grasp_net.py", line 127, in encode
    return self.net.encode(pcs, input_features)
  File "/home/sirius/sirui/contact_planning_dexterous_hand/neurals/network.py", line 210, in encode
    xyz, xyz_features = module(xyz, xyz_features)
  File "/home/sirius/anaconda3/envs/taichi/lib/python3.8/site-packages/torch/nn/modules/module.py", line 1130, in _call_impl
    return forward_call(*input, **kwargs)
  File "/home/sirius/anaconda3/envs/taichi/lib/python3.8/site-packages/pointnet2_ops/pointnet2_modules.py", line 62, in forward
    new_features = self.groupers[i](
  File "/home/sirius/anaconda3/envs/taichi/lib/python3.8/site-packages/torch/nn/modules/module.py", line 1130, in _call_impl
    return forward_call(*input, **kwargs)
  File "/home/sirius/anaconda3/envs/taichi/lib/python3.8/site-packages/pointnet2_ops/pointnet2_utils.py", line 320, in forward
    grouped_features = grouping_operation(features, idx)
  File "/home/sirius/anaconda3/envs/taichi/lib/python3.8/site-packages/pointnet2_ops/pointnet2_utils.py", line 214, in forward
    return _ext.group_points(features, idx)
RuntimeError: points.scalar_type() == at::ScalarType::Float INTERNAL ASSERT FAILED at "/tmp/pip-req-build-t9j9oon0/pointnet2_ops/_ext-src/src/group_points.cpp":15, please report a bug to PyTorch. points must be a float tensor